<?xml version="1.0" ?>
<!-- =================================================================================== -->
<!-- |    This document was autogenerated by xacro from rigatoni.urdf.xacro            | -->
<!-- |    EDITING THIS FILE BY HAND IS NOT RECOMMENDED                                 | -->
<!-- =================================================================================== -->
<robot name="rigatoni">
  <!-- <xacro:include filename="$(find velodyne_description)/urdf/VLP-16.urdf.xacro"/> -->
  <!-- <xacro:include filename="$(find rr_description)/" -->
  <!-- ************************** Links *************************** -->
  <link name="base_footprint">
    <inertial>
      <mass value="0.0001"/>
      <inertia ixx="0.0001" ixy="0" ixz="0" iyy="0.0001" iyz="0" izz="0.0001"/>
    </inertial>
  </link>
  <link name="body_visual_origin">
    <inertial>
      <mass value="0.0001"/>
      <inertia ixx="0.0001" ixy="0" ixz="0" iyy="0.0001" iyz="0" izz="0.0001"/>
    </inertial>
    <visual>
      <geometry>
        <!-- <mesh filename="$(find rr_description)/meshes/rigatoni.stl" scale="0.01 0.01 0.01"/> -->
      </geometry>
    </visual>
    <!--            <collision>-->
    <!--                <xacro:mesh_geometry/>-->
    <!--            </collision>-->
  </link>
  <gazebo reference="body_visual_origin">
    <material>Gazebo/Grey</material>
  </gazebo>
  <gazebo reference="body_visual_origin">
    <collision>
      <surface>
        <contact>
          <collide_bitmask>0x1</collide_bitmask>
        </contact>
      </surface>
    </collision>
  </gazebo>
  <link name="body_inertial_center">
    <inertial>
      <mass value="50"/>
      <inertia ixx="0.5" ixy="0" ixz="0" iyy="0.75" iyz="0" izz="0.5"/>
    </inertial>
  </link>
  <gazebo reference="body_inertial_center"/>
  <!-- ************************** Joints *************************** -->
  <joint name="base_footprint_to_mesh_origin" type="fixed">
    <parent link="base_footprint"/>
    <child link="body_visual_origin"/>
    <origin rpy="1.5707963267948966 0 1.5707963267948966" xyz="0.53 0 -0.05"/>
  </joint>
  <joint name="base_footprint_to_body_inertial_center" type="fixed">
    <parent link="base_footprint"/>
    <child link="body_inertial_center"/>
    <origin xyz="0.4 0 0.1"/>
  </joint>
  <link name="wheel_BL">
    <inertial>
      <mass value="0.01"/>
      <inertia ixx="0.001" ixy="0" ixz="0" iyy="0.001" iyz="0" izz="0.0078125"/>
    </inertial>
    <visual>
      <geometry>
        <cylinder length="0.22" radius="0.125"/>
      </geometry>
    </visual>
    <collision>
      <geometry>
        <cylinder length="0.22" radius="0.125"/>
      </geometry>
    </collision>
  </link>
  <gazebo reference="wheel_BL">
    <mu1>0.7</mu1>
    <mu2>0.7</mu2>
    <kp>1000000</kp>
    <kd>1000000</kd>
    <collision>
      <surface>
        <contact>
          <collide_bitmask>0x1</collide_bitmask>
        </contact>
      </surface>
    </collision>
  </gazebo>
  <gazebo reference="wheel_BL">
    <material>Gazebo/Black</material>
  </gazebo>
  <link name="wheel_BR">
    <inertial>
      <mass value="0.01"/>
      <inertia ixx="0.001" ixy="0" ixz="0" iyy="0.001" iyz="0" izz="0.0078125"/>
    </inertial>
    <visual>
      <geometry>
        <cylinder length="0.22" radius="0.125"/>
      </geometry>
    </visual>
    <collision>
      <geometry>
        <cylinder length="0.22" radius="0.125"/>
      </geometry>
    </collision>
  </link>
  <gazebo reference="wheel_BR">
    <mu1>0.7</mu1>
    <mu2>0.7</mu2>
    <kp>1000000</kp>
    <kd>1000000</kd>
    <collision>
      <surface>
        <contact>
          <collide_bitmask>0x1</collide_bitmask>
        </contact>
      </surface>
    </collision>
  </gazebo>
  <gazebo reference="wheel_BR">
    <material>Gazebo/Black</material>
  </gazebo>
  <link name="wheel_FL">
    <inertial>
      <mass value="0.01"/>
      <inertia ixx="0.001" ixy="0" ixz="0" iyy="0.001" iyz="0" izz="0.0078125"/>
    </inertial>
    <visual>
      <geometry>
        <cylinder length="0.1" radius="0.125"/>
      </geometry>
    </visual>
    <collision>
      <geometry>
        <cylinder length="0.1" radius="0.125"/>
      </geometry>
    </collision>
  </link>
  <gazebo reference="wheel_FL">
    <mu1>0.7</mu1>
    <mu2>0.7</mu2>
    <kp>1000000</kp>
    <kd>1000000</kd>
    <collision>
      <surface>
        <contact>
          <collide_bitmask>0x1</collide_bitmask>
        </contact>
      </surface>
    </collision>
  </gazebo>
  <gazebo reference="wheel_FL">
    <material>Gazebo/Black</material>
  </gazebo>
  <link name="wheel_FR">
    <inertial>
      <mass value="0.01"/>
      <inertia ixx="0.001" ixy="0" ixz="0" iyy="0.001" iyz="0" izz="0.0078125"/>
    </inertial>
    <visual>
      <geometry>
        <cylinder length="0.1" radius="0.125"/>
      </geometry>
    </visual>
    <collision>
      <geometry>
        <cylinder length="0.1" radius="0.125"/>
      </geometry>
    </collision>
  </link>
  <gazebo reference="wheel_FR">
    <mu1>0.7</mu1>
    <mu2>0.7</mu2>
    <kp>1000000</kp>
    <kd>1000000</kd>
    <collision>
      <surface>
        <contact>
          <collide_bitmask>0x1</collide_bitmask>
        </contact>
      </surface>
    </collision>
  </gazebo>
  <gazebo reference="wheel_FR">
    <material>Gazebo/Black</material>
  </gazebo>
  <link name="steering_link_left">
    <inertial>
      <mass value="0.0001"/>
      <inertia ixx="0.0001" ixy="0" ixz="0" iyy="0.0001" iyz="0" izz="0.0001"/>
    </inertial>
  </link>
  <link name="steering_link_right">
    <inertial>
      <mass value="0.0001"/>
      <inertia ixx="0.0001" ixy="0" ixz="0" iyy="0.0001" iyz="0" izz="0.0001"/>
    </inertial>
  </link>
  <link name="gps_link">
    <inertial>
      <mass value="0.0001"/>
      <inertia ixx="0.0001" ixy="0" ixz="0" iyy="0.0001" iyz="0" izz="0.0001"/>
    </inertial>
    <visual>
      <geometry>
        <box size="0.05 0.05 0.05"/>
      </geometry>
    </visual>
  </link>
  <gazebo reference="gps_link">
    <material>Gazebo/Gold</material>
  </gazebo>
  <link name="camera">
    <inertial>
      <mass value="0.0001"/>
      <inertia ixx="0.0001" ixy="0" ixz="0" iyy="0.0001" iyz="0" izz="0.0001"/>
    </inertial>
    <visual>
      <geometry>
        <box size="0.05 0.05 0.05"/>
      </geometry>
    </visual>
    <visual>
      <origin rpy="0 1.5707963267948966 0" xyz="0.05 0 0"/>
      <geometry>
        <cylinder length="0.05" radius="0.03"/>
      </geometry>
    </visual>
  </link>
  <gazebo reference="camera">
    <material>Gazebo/Gold</material>
  </gazebo>
  <link name="imu_top_link">
    <inertial>
      <mass value="0.0001"/>
      <inertia ixx="0.0001" ixy="0" ixz="0" iyy="0.0001" iyz="0" izz="0.0001"/>
    </inertial>
    <visual>
      <geometry>
        <box size="0.05 0.05 0.05"/>
      </geometry>
    </visual>
  </link>
  <gazebo reference="imu_top_link">
    <material>Gazebo/Gold</material>
  </gazebo>
  <link name="imu_bottom_link">
    <inertial>
      <mass value="0.0001"/>
      <inertia ixx="0.0001" ixy="0" ixz="0" iyy="0.0001" iyz="0" izz="0.0001"/>
    </inertial>
    <visual>
      <geometry>
        <box size="0.05 0.05 0.05"/>
      </geometry>
    </visual>
  </link>
  <gazebo reference="imu_bottom_link">
    <material>Gazebo/Gold</material>
  </gazebo>
  <link name="april_2">
    <inertial>
      <mass value="0.0001"/>
      <inertia ixx="0.0001" ixy="0" ixz="0" iyy="0.0001" iyz="0" izz="0.0001"/>
    </inertial>
    <visual>
      <geometry>
        <box size="0.001 0.127 0.127 "/>
      </geometry>
    </visual>
  </link>
  <gazebo reference="april_2">
    <material>tag36_11_00052</material>
  </gazebo>
  <link name="april_3">
    <inertial>
      <mass value="0.0001"/>
      <inertia ixx="0.0001" ixy="0" ixz="0" iyy="0.0001" iyz="0" izz="0.0001"/>
    </inertial>
    <visual>
      <geometry>
        <box size="0.001 0.127 0.127 "/>
      </geometry>
    </visual>
  </link>
  <gazebo reference="april_3">
    <material>tag36_11_00053</material>
  </gazebo>
  <link name="april_4">
    <inertial>
      <mass value="0.0001"/>
      <inertia ixx="0.0001" ixy="0" ixz="0" iyy="0.0001" iyz="0" izz="0.0001"/>
    </inertial>
    <visual>
      <geometry>
        <box size="0.001 0.127 0.127 "/>
      </geometry>
    </visual>
  </link>
  <gazebo reference="april_4">
    <material>tag36_11_00054</material>
  </gazebo>
  <link name="april_5">
    <inertial>
      <mass value="0.0001"/>
      <inertia ixx="0.0001" ixy="0" ixz="0" iyy="0.0001" iyz="0" izz="0.0001"/>
    </inertial>
    <visual>
      <geometry>
        <box size="0.001 0.127 0.127 "/>
      </geometry>
    </visual>
  </link>
  <gazebo reference="april_5">
    <material>tag36_11_00055</material>
  </gazebo>
  <link name="april_6">
    <inertial>
      <mass value="0.0001"/>
      <inertia ixx="0.0001" ixy="0" ixz="0" iyy="0.0001" iyz="0" izz="0.0001"/>
    </inertial>
    <visual>
      <geometry>
        <box size="0.001 0.127 0.127 "/>
      </geometry>
    </visual>
  </link>
  <gazebo reference="april_6">
    <material>tag36_11_00056</material>
  </gazebo>
  <!-- ************************** Joints *************************** -->
  <joint name="base_footprint_to_wheel_BL" type="continuous">
    <parent link="base_footprint"/>
    <child link="wheel_BL"/>
    <origin rpy="-1.5707963267948966 0 0" xyz="0 0.6 0.0325"/>
    <axis xyz="0 0 1"/>
  </joint>
  <gazebo reference="base_footprint_to_wheel_BL"/>
  <joint name="base_footprint_to_wheel_BR" type="continuous">
    <parent link="base_footprint"/>
    <child link="wheel_BR"/>
    <origin rpy="-1.5707963267948966 0 0" xyz="0 -0.6 0.0325"/>
    <axis xyz="0 0 1"/>
  </joint>
  <gazebo reference="base_footprint_to_wheel_BR"/>
  <joint name="base_footprint_to_steering_link_left" type="revolute">
    <parent link="base_footprint"/>
    <child link="steering_link_left"/>
    <origin rpy="0 0 0" xyz="1.03 0.6 0.0625"/>
    <axis xyz="0 0 1"/>
    <limit effort="10000.0" lower="-0.3" upper="0.3" velocity="2.0"/>
  </joint>
  <gazebo reference="base_footprint_to_steering_link_left"/>
  <joint name="steering_link_left_to_wheel_FL" type="continuous">
    <origin rpy="1.5707963267948966 0 0" xyz="0 0 -0.037"/>
    <parent link="steering_link_left"/>
    <child link="wheel_FL"/>
    <axis xyz="0 0 1"/>
  </joint>
  <gazebo reference="steering_link_left_to_wheel_FL"/>
  <joint name="base_footprint_to_steering_link_right" type="revolute">
    <parent link="base_footprint"/>
    <child link="steering_link_right"/>
    <origin rpy="0 0 0" xyz="1.03 -0.6 0.0625"/>
    <axis xyz="0 0 1"/>
    <limit effort="10000.0" lower="-0.3" upper="0.3" velocity="2.0"/>
  </joint>
  <gazebo reference="base_footprint_to_steering_link_right"/>
  <joint name="steering_link_right_to_wheel_FR" type="continuous">
    <origin rpy="1.5707963267948966 0 0" xyz="0 0 -0.037"/>
    <parent link="steering_link_right"/>
    <child link="wheel_FR"/>
    <axis xyz="0 0 1"/>
  </joint>
  <gazebo reference="steering_link_right_to_wheel_FR"/>
  <link name="camera_optical">
    <inertial>
      <mass value="0.0001"/>
      <inertia ixx="0.0001" ixy="0" ixz="0" iyy="0.0001" iyz="0" izz="0.0001"/>
    </inertial>
  </link>
  <joint name="camera_to_optical" type="fixed">
    <parent link="camera"/>
    <child link="camera_optical"/>
    <origin rpy="-1.5707963267948966 0 -1.5707963267948966" xyz="0 0 0"/>
  </joint>
  <joint name="base_footprint_to_gps_link" type="fixed">
    <parent link="base_footprint"/>
    <child link="gps_link"/>
    <origin rpy="0 0 0" xyz="0.55 0.39 1.22"/>
  </joint>
  <joint name="base_footprint_to_camera" type="fixed">
    <parent link="base_footprint"/>
    <child link="camera"/>
    <origin rpy="0 0.4 0" xyz="0.61 0.39 1.03"/>
  </joint>
  <joint name="base_footprint_to_imu_bottom_link" type="fixed">
    <parent link="base_footprint"/>
    <child link="imu_bottom_link"/>
    <origin rpy="0 0 0" xyz="0 0 0.21"/>
  </joint>
  <joint name="base_footprint_to_imu_top_link" type="fixed">
    <parent link="base_footprint"/>
    <child link="imu_top_link"/>
    <origin rpy="0 0 0" xyz="0.60 0.39 0.95"/>
  </joint>
  <joint name="base_footprint_to_april_2" type="fixed">
    <parent link="base_footprint"/>
    <child link="april_2"/>
    <origin rpy="0 0 1.5707963267948966" xyz=".48  -0.55 0.26"/>
  </joint>
  <joint name="base_footprint_to_april_3" type="fixed">
    <parent link="base_footprint"/>
    <child link="april_3"/>
    <origin rpy="0 0 0.7853981633974483" xyz="-.19 -0.43 0.26"/>
  </joint>
  <joint name="base_footprint_to_april_4" type="fixed">
    <parent link="base_footprint"/>
    <child link="april_4"/>
    <origin rpy="0 0 0" xyz="-.38  0    0.26"/>
  </joint>
  <joint name="base_footprint_to_april_5" type="fixed">
    <parent link="base_footprint"/>
    <child link="april_5"/>
    <origin rpy="0 0 -0.7853981633974483" xyz="-.19  0.43 0.26"/>
  </joint>
  <joint name="base_footprint_to_april_6" type="fixed">
    <parent link="base_footprint"/>
    <child link="april_6"/>
    <origin rpy="0 0 1.5707963267948966" xyz=".48   0.55 0.26"/>
  </joint>
  <!-- ******************* Sensors *********************** -->
  <!-- Velodyne Puck VLP-16 -->
  <!-- <xacro:VLP-16 parent="base_footprint" name="lidar" topic="/velodyne_points" hz="10" samples="500" gpu="true">
        <origin xyz="1.175 0 0.175" rpy="0 0 0" />
    </xacro:VLP-16> -->
  <!-- FLIR Blackfly + wide-angle lens -->
  <gazebo reference="camera">
    <sensor name="camera_sensor" type="camera">
      <camera>
        <horizontal_fov>1.6955</horizontal_fov>
        <image>
          <width>1280</width>
          <height>964</height>
          <format>R8G8B8</format>
        </image>
        <clip>
          <near>0.05</near>
          <far>100</far>
        </clip>
        <noise>
          <type>gaussian</type>
          <mean>0.0</mean>
          <stddev>0.007</stddev>
        </noise>
      </camera>
      <always_on>true</always_on>
      <update_rate>15</update_rate>
      <plugin filename="libgazebo_ros_camera.so" name="camera_controller">
        <alwaysOn>true</alwaysOn>
        <cameraName>camera</cameraName>
        <imageTopicName>image_color_rect</imageTopicName>
        <cameraInfoTopicName>camera_info</cameraInfoTopicName>
        <frameName>camera_optical</frameName>
        <distortionK1>0.0</distortionK1>
        <distortionK2>0.0</distortionK2>
        <distortionK3>0.0</distortionK3>
        <distortionT1>0.0</distortionT1>
        <distortionT2>0.0</distortionT2>
      </plugin>
    </sensor>
  </gazebo>
  <!-- IMU -->
  <gazebo reference="imu_top_link">
    <gravity>true</gravity>
    <sensor name="imu_sensor" type="imu">
      <always_on>true</always_on>
      <update_rate>100</update_rate>
      <visualize>true</visualize>
      <topic>__default_topic__</topic>
      <plugin filename="libgazebo_ros_imu_sensor.so" name="imu_plugin">
        <topicName>imu_top</topicName>
        <bodyName>imu_top_link</bodyName>
        <updateRateHZ>20.0</updateRateHZ>
        <gaussianNoise>0.005</gaussianNoise>
        <xyzOffset>0 0 0</xyzOffset>
        <rpyOffset>0 0 0</rpyOffset>
        <frameName>imu_top_link</frameName>
      </plugin>
      <pose>0 0 0 0 0 0</pose>
    </sensor>
  </gazebo>
  <!-- IMU -->
  <gazebo reference="imu_bottom_link">
    <gravity>true</gravity>
    <sensor name="imu_sensor_bottom" type="imu">
      <always_on>true</always_on>
      <update_rate>100</update_rate>
      <visualize>true</visualize>
      <topic>__default_topic__</topic>
      <plugin filename="libgazebo_ros_imu_sensor.so" name="imu_plugin">
        <topicName>imu_bottom</topicName>
        <bodyName>imu_bottom_link</bodyName>
        <updateRateHZ>20.0</updateRateHZ>
        <gaussianNoise>0.005</gaussianNoise>
        <xyzOffset>0 0 0</xyzOffset>
        <rpyOffset>0 0 0</rpyOffset>
        <frameName>imu_bottom_link</frameName>
      </plugin>
      <pose>0 0 0 0 0 0</pose>
    </sensor>
  </gazebo>
  <!-- GPS -->
  <gazebo>
    <plugin filename="libhector_gazebo_ros_gps.so" name="gps_controller">
      <robotNamespace>/</robotNamespace>
      <updateRate>10</updateRate>
      <bodyName>gps_link</bodyName>
      <frameId>gps_link</frameId>
      <topicName>gps/fix</topicName>
      <velocityTopicName>gps/vel</velocityTopicName>
      <referenceLatitude>33.8</referenceLatitude>
      <referenceLongitude>-84.4</referenceLongitude>
      <referenceHeading>0</referenceHeading>
      <referenceAltitude>0</referenceAltitude>
      <drift>0.2 0.2 0.2</drift>
      <driftFrequency>0.01 0.01 0.01</driftFrequency>
      <gaussianNoise>0.05 0.05 0.05</gaussianNoise>
      <velocityDrift>0.05 0.05 0.05</velocityDrift>
      <velocityDriftFrequency>0.1 0.1 0.1</velocityDriftFrequency>
      <velocityGaussianNoise>0.05 0.05 0.05</velocityGaussianNoise>
    </plugin>
  </gazebo>
  <!-- ground-truth localization plugin -->
  <gazebo>
    <plugin filename="libgazebo_ros_p3d.so" name="ground_truth_tracker">
      <alwaysOn>true</alwaysOn>
      <updateRate>10.0</updateRate>
      <bodyName>base_footprint</bodyName>
      <topicName>/odometry/ground_truth</topicName>
      <gaussianNoise>0.0</gaussianNoise>
      <frameName>world</frameName>
      <xyzOffsets>0 0 0</xyzOffsets>
      <rpyOffsets>0 0 0</rpyOffsets>
    </plugin>
  </gazebo>
  <!-- ****************** Actuators ********************** -->
  <gazebo>
    <plugin filename="libgazebo_ros2_control.so" name="gazebo_ros2_control">
      <robot_namespace>rigatoni</robot_namespace>
      <robot_param>robot_description</robot_param>
      <robot_param_node>robot_state_publisher</robot_param_node>
      <!-- <parameters>$(find rr_description)/src/conf/controller.yaml</parameters> -->
    </plugin>
  </gazebo>
  <ros2_control name="GazeboSystem" type="system">
    <hardware>
      <plugin>gazebo_ros2_control/GazeboSystem</plugin>
    </hardware>
    <joint name="base_footprint_to_wheel_BL">
      <command_interface name="effort">
        <param name="min">-1</param>
        <param name="max">1</param>
      </command_interface>
      <state_interface name="position"/>
      <state_interface name="velocity"/>
      <state_interface name="effort"/>
    </joint>
    <joint name="base_footprint_to_wheel_BR">
      <command_interface name="effort">
        <param name="min">-1</param>
        <param name="max">1</param>
      </command_interface>
      <state_interface name="position"/>
      <state_interface name="velocity"/>
      <state_interface name="effort"/>
    </joint>
    <joint name="base_footprint_to_steering_link_left">
      <command_interface name="position">
        <param name="min">-1</param>
        <param name="max">1</param>
      </command_interface>
      <state_interface name="position"/>
      <state_interface name="velocity"/>
    </joint>
    <joint name="base_footprint_to_steering_link_right">
      <command_interface name="position">
        <param name="min">-1</param>
        <param name="max">1</param>
      </command_interface>
      <state_interface name="position"/>
      <state_interface name="velocity"/>
    </joint>
  </ros2_control>
</robot>
