<?xml version="1.0" ?>
<!-- =================================================================================== -->
<!-- |    This document was autogenerated by xacro from /home/dani/catkin_ws/src/roboracing-software/rr_description/urdf/rigatoni_opponent.urdf.xacro | -->
<!-- |    EDITING THIS FILE BY HAND IS NOT RECOMMENDED                                 | -->
<!-- =================================================================================== -->
<robot name="rigatoni_opponent">
  <!-- ************************** Links *************************** -->
  <link name="opponent_base_footprint">
    <inertial>
      <mass value="0.0001"/>
      <inertia ixx="0.0001" ixy="0" ixz="0" iyy="0.0001" iyz="0" izz="0.0001"/>
    </inertial>
  </link>
  <link name="body_visual_origin">
    <inertial>
      <mass value="0.0001"/>
      <inertia ixx="0.0001" ixy="0" ixz="0" iyy="0.0001" iyz="0" izz="0.0001"/>
    </inertial>
    <visual>
      <geometry>
        <mesh filename="package://rr_description/meshes/rigatoni.stl" scale="0.01 0.01 0.01"/>
      </geometry>
    </visual>
    <!--            <collision>-->
    <!--                <xacro:mesh_geometry/>-->
    <!--            </collision>-->
  </link>
  <gazebo reference="body_visual_origin">
    <material>Gazebo/Grey</material>
  </gazebo>
  <gazebo reference="body_visual_origin">
    <collision>
      <surface>
        <contact>
          <collide_bitmask>0x1</collide_bitmask>
        </contact>
      </surface>
    </collision>
  </gazebo>
  <link name="body_inertial_center">
    <inertial>
      <mass value="50"/>
      <inertia ixx="0.5" ixy="0" ixz="0" iyy="0.75" iyz="0" izz="0.5"/>
    </inertial>
  </link>
  <gazebo reference="body_inertial_center"/>
  <!-- ************************** Joints *************************** -->
  <joint name="opponent_base_footprint_to_mesh_origin" type="fixed">
    <parent link="opponent_base_footprint"/>
    <child link="body_visual_origin"/>
    <origin rpy="1.5707963267948966 0 1.5707963267948966" xyz="0.53 0 0"/>
  </joint>
  <joint name="opponent_base_footprint_to_body_inertial_center" type="fixed">
    <parent link="opponent_base_footprint"/>
    <child link="body_inertial_center"/>
    <origin xyz="0.4 0 0.1"/>
  </joint>
  <link name="wheel_BL">
    <inertial>
      <mass value="0.01"/>
      <inertia ixx="0.001" ixy="0" ixz="0" iyy="0.001" iyz="0" izz="0.0078125"/>
    </inertial>
    <visual>
      <geometry>
        <cylinder length="0.14" radius="0.125"/>
      </geometry>
    </visual>
    <collision>
      <geometry>
        <cylinder length="0.14" radius="0.125"/>
      </geometry>
    </collision>
  </link>
  <gazebo reference="wheel_BL">
    <mu1>0.7</mu1>
    <mu2>0.7</mu2>
    <kp>1000000</kp>
    <kd>1000000</kd>
    <collision>
      <surface>
        <contact>
          <collide_bitmask>0x1</collide_bitmask>
        </contact>
      </surface>
    </collision>
  </gazebo>
  <gazebo reference="wheel_BL">
    <material>Gazebo/Black</material>
  </gazebo>
  <link name="wheel_BR">
    <inertial>
      <mass value="0.01"/>
      <inertia ixx="0.001" ixy="0" ixz="0" iyy="0.001" iyz="0" izz="0.0078125"/>
    </inertial>
    <visual>
      <geometry>
        <cylinder length="0.14" radius="0.125"/>
      </geometry>
    </visual>
    <collision>
      <geometry>
        <cylinder length="0.14" radius="0.125"/>
      </geometry>
    </collision>
  </link>
  <gazebo reference="wheel_BR">
    <mu1>0.7</mu1>
    <mu2>0.7</mu2>
    <kp>1000000</kp>
    <kd>1000000</kd>
    <collision>
      <surface>
        <contact>
          <collide_bitmask>0x1</collide_bitmask>
        </contact>
      </surface>
    </collision>
  </gazebo>
  <gazebo reference="wheel_BR">
    <material>Gazebo/Black</material>
  </gazebo>
  <link name="wheel_FL">
    <inertial>
      <mass value="0.01"/>
      <inertia ixx="0.001" ixy="0" ixz="0" iyy="0.001" iyz="0" izz="0.0078125"/>
    </inertial>
    <visual>
      <geometry>
        <cylinder length="0.14" radius="0.125"/>
      </geometry>
    </visual>
    <collision>
      <geometry>
        <cylinder length="0.14" radius="0.125"/>
      </geometry>
    </collision>
  </link>
  <gazebo reference="wheel_FL">
    <mu1>0.7</mu1>
    <mu2>0.7</mu2>
    <kp>1000000</kp>
    <kd>1000000</kd>
    <collision>
      <surface>
        <contact>
          <collide_bitmask>0x1</collide_bitmask>
        </contact>
      </surface>
    </collision>
  </gazebo>
  <gazebo reference="wheel_FL">
    <material>Gazebo/Black</material>
  </gazebo>
  <link name="wheel_FR">
    <inertial>
      <mass value="0.01"/>
      <inertia ixx="0.001" ixy="0" ixz="0" iyy="0.001" iyz="0" izz="0.0078125"/>
    </inertial>
    <visual>
      <geometry>
        <cylinder length="0.14" radius="0.125"/>
      </geometry>
    </visual>
    <collision>
      <geometry>
        <cylinder length="0.14" radius="0.125"/>
      </geometry>
    </collision>
  </link>
  <gazebo reference="wheel_FR">
    <mu1>0.7</mu1>
    <mu2>0.7</mu2>
    <kp>1000000</kp>
    <kd>1000000</kd>
    <collision>
      <surface>
        <contact>
          <collide_bitmask>0x1</collide_bitmask>
        </contact>
      </surface>
    </collision>
  </gazebo>
  <gazebo reference="wheel_FR">
    <material>Gazebo/Black</material>
  </gazebo>
  <link name="steering_link_left">
    <inertial>
      <mass value="0.0001"/>
      <inertia ixx="0.0001" ixy="0" ixz="0" iyy="0.0001" iyz="0" izz="0.0001"/>
    </inertial>
  </link>
  <link name="steering_link_right">
    <inertial>
      <mass value="0.0001"/>
      <inertia ixx="0.0001" ixy="0" ixz="0" iyy="0.0001" iyz="0" izz="0.0001"/>
    </inertial>
  </link>
  <link name="gps_link">
    <inertial>
      <mass value="0.0001"/>
      <inertia ixx="0.0001" ixy="0" ixz="0" iyy="0.0001" iyz="0" izz="0.0001"/>
    </inertial>
    <visual>
      <geometry>
        <box size="0.05 0.05 0.05"/>
      </geometry>
    </visual>
  </link>
  <gazebo reference="gps_link">
    <material>Gazebo/Gold</material>
  </gazebo>
  <link name="camera">
    <inertial>
      <mass value="0.0001"/>
      <inertia ixx="0.0001" ixy="0" ixz="0" iyy="0.0001" iyz="0" izz="0.0001"/>
    </inertial>
    <visual>
      <geometry>
        <box size="0.05 0.05 0.05"/>
      </geometry>
    </visual>
    <visual>
      <origin rpy="0 1.5707963267948966 0" xyz="0.05 0 0"/>
      <geometry>
        <cylinder length="0.05" radius="0.03"/>
      </geometry>
    </visual>
  </link>
  <gazebo reference="camera">
    <material>Gazebo/Gold</material>
  </gazebo>
  <link name="imu_top_link">
    <inertial>
      <mass value="0.0001"/>
      <inertia ixx="0.0001" ixy="0" ixz="0" iyy="0.0001" iyz="0" izz="0.0001"/>
    </inertial>
    <visual>
      <geometry>
        <box size="0.05 0.05 0.05"/>
      </geometry>
    </visual>
  </link>
  <gazebo reference="imu_top_link">
    <material>Gazebo/Gold</material>
  </gazebo>
  <link name="imu_bottom_link">
    <inertial>
      <mass value="0.0001"/>
      <inertia ixx="0.0001" ixy="0" ixz="0" iyy="0.0001" iyz="0" izz="0.0001"/>
    </inertial>
    <visual>
      <geometry>
        <box size="0.05 0.05 0.05"/>
      </geometry>
    </visual>
  </link>
  <gazebo reference="imu_bottom_link">
    <material>Gazebo/Gold</material>
  </gazebo>
  <link name="white">
    <inertial>
      <mass value="0.0001"/>
      <inertia ixx="0.0001" ixy="0" ixz="0" iyy="0.0001" iyz="0" izz="0.0001"/>
    </inertial>
    <visual>
      <geometry>
        <box size="0.001 0.3 0.3 "/>
      </geometry>
    </visual>
  </link>
  <gazebo reference="white">
    <material>none</material>
  </gazebo>
  <link name="white_back_left">
    <inertial>
      <mass value="0.0001"/>
      <inertia ixx="0.0001" ixy="0" ixz="0" iyy="0.0001" iyz="0" izz="0.0001"/>
    </inertial>
    <visual>
      <geometry>
        <box size="0.001 0.3 0.3 "/>
      </geometry>
    </visual>
  </link>
  <gazebo reference="white_back_left">
    <material>none</material>
  </gazebo>
  <link name="white_side_left">
    <inertial>
      <mass value="0.0001"/>
      <inertia ixx="0.0001" ixy="0" ixz="0" iyy="0.0001" iyz="0" izz="0.0001"/>
    </inertial>
    <visual>
      <geometry>
        <box size="0.001 0.3 0.3 "/>
      </geometry>
    </visual>
  </link>
  <gazebo reference="white_side_left">
    <material>none</material>
  </gazebo>
  <link name="white_front_left">
    <inertial>
      <mass value="0.0001"/>
      <inertia ixx="0.0001" ixy="0" ixz="0" iyy="0.0001" iyz="0" izz="0.0001"/>
    </inertial>
    <visual>
      <geometry>
        <box size="0.001 0.3 0.3 "/>
      </geometry>
    </visual>
  </link>
  <gazebo reference="white_front_left">
    <material>none</material>
  </gazebo>
  <link name="white_front_mid">
    <inertial>
      <mass value="0.0001"/>
      <inertia ixx="0.0001" ixy="0" ixz="0" iyy="0.0001" iyz="0" izz="0.0001"/>
    </inertial>
    <visual>
      <geometry>
        <box size="0.001 0.3 0.3 "/>
      </geometry>
    </visual>
  </link>
  <gazebo reference="white_front_mid">
    <material>none</material>
  </gazebo>
  <link name="white_front_right">
    <inertial>
      <mass value="0.0001"/>
      <inertia ixx="0.0001" ixy="0" ixz="0" iyy="0.0001" iyz="0" izz="0.0001"/>
    </inertial>
    <visual>
      <geometry>
        <box size="0.001 0.3 0.3 "/>
      </geometry>
    </visual>
  </link>
  <link name="white_side_right">
    <inertial>
      <mass value="0.0001"/>
      <inertia ixx="0.0001" ixy="0" ixz="0" iyy="0.0001" iyz="0" izz="0.0001"/>
    </inertial>
    <visual>
      <geometry>
        <box size="0.001 0.3 0.3 "/>
      </geometry>
    </visual>
  </link>
  <link name="white_back_right">
    <inertial>
      <mass value="0.0001"/>
      <inertia ixx="0.0001" ixy="0" ixz="0" iyy="0.0001" iyz="0" izz="0.0001"/>
    </inertial>
    <visual>
      <geometry>
        <box size="0.001 0.3 0.3 "/>
      </geometry>
    </visual>
  </link>
  <link name="4_april">
    <inertial>
      <mass value="0.0001"/>
      <inertia ixx="0.0001" ixy="0" ixz="0" iyy="0.0001" iyz="0" izz="0.0001"/>
    </inertial>
    <visual>
      <geometry>
        <box size="0.001 0.3 0.3 "/>
      </geometry>
    </visual>
  </link>
  <gazebo reference="4_april">
    <material>Apriltag4</material>
  </gazebo>
  <link name="5_april">
    <inertial>
      <mass value="0.0001"/>
      <inertia ixx="0.0001" ixy="0" ixz="0" iyy="0.0001" iyz="0" izz="0.0001"/>
    </inertial>
    <visual>
      <geometry>
        <box size="0.001 0.3 0.3 "/>
      </geometry>
    </visual>
  </link>
  <gazebo reference="5_april">
    <material>Apriltag5</material>
  </gazebo>
  <link name="6_april">
    <inertial>
      <mass value="0.0001"/>
      <inertia ixx="0.0001" ixy="0" ixz="0" iyy="0.0001" iyz="0" izz="0.0001"/>
    </inertial>
    <visual>
      <geometry>
        <box size="0.001 0.3 0.3 "/>
      </geometry>
    </visual>
  </link>
  <gazebo reference="6_april">
    <material>Apriltag6</material>
  </gazebo>
  <link name="7_april">
    <inertial>
      <mass value="0.0001"/>
      <inertia ixx="0.0001" ixy="0" ixz="0" iyy="0.0001" iyz="0" izz="0.0001"/>
    </inertial>
    <visual>
      <geometry>
        <box size="0.001 0.3 0.3 "/>
      </geometry>
    </visual>
  </link>
  <gazebo reference="7_april">
    <material>Apriltag7</material>
  </gazebo>
  <link name="0_april">
    <inertial>
      <mass value="0.0001"/>
      <inertia ixx="0.0001" ixy="0" ixz="0" iyy="0.0001" iyz="0" izz="0.0001"/>
    </inertial>
    <visual>
      <geometry>
        <box size="0.001 0.3 0.3 "/>
      </geometry>
    </visual>
  </link>
  <gazebo reference="0_april">
    <material>Apriltag0</material>
  </gazebo>
  <link name="1_april">
    <inertial>
      <mass value="0.0001"/>
      <inertia ixx="0.0001" ixy="0" ixz="0" iyy="0.0001" iyz="0" izz="0.0001"/>
    </inertial>
    <visual>
      <geometry>
        <box size="0.001 0.3 0.3 "/>
      </geometry>
    </visual>
  </link>
  <gazebo reference="1_april">
    <material>Apriltag1</material>
  </gazebo>
  <link name="2_april">
    <inertial>
      <mass value="0.0001"/>
      <inertia ixx="0.0001" ixy="0" ixz="0" iyy="0.0001" iyz="0" izz="0.0001"/>
    </inertial>
    <visual>
      <geometry>
        <box size="0.001 0.3 0.3 "/>
      </geometry>
    </visual>
  </link>
  <gazebo reference="2_april">
    <material>Apriltag2</material>
  </gazebo>
  <link name="3_april">
    <inertial>
      <mass value="0.0001"/>
      <inertia ixx="0.0001" ixy="0" ixz="0" iyy="0.0001" iyz="0" izz="0.0001"/>
    </inertial>
    <visual>
      <geometry>
        <box size="0.001 0.3 0.3 "/>
      </geometry>
    </visual>
  </link>
  <gazebo reference="3_april">
    <material>Apriltag3</material>
  </gazebo>
  <!-- ************************** Joints *************************** -->
  <joint name="opponent_base_footprint_to_wheel_BL" type="continuous">
    <parent link="opponent_base_footprint"/>
    <child link="wheel_BL"/>
    <origin rpy="-1.5707963267948966 0 0" xyz="0 0.52 0.0325"/>
    <axis xyz="0 0 1"/>
  </joint>
  <gazebo reference="opponent_base_footprint_to_wheel_BL"/>
  <joint name="opponent_base_footprint_to_wheel_BR" type="continuous">
    <parent link="opponent_base_footprint"/>
    <child link="wheel_BR"/>
    <origin rpy="-1.5707963267948966 0 0" xyz="0 -0.52 0.0325"/>
    <axis xyz="0 0 1"/>
  </joint>
  <gazebo reference="opponent_base_footprint_to_wheel_BR"/>
  <joint name="opponent_base_footprint_to_steering_link_left" type="revolute">
    <parent link="opponent_base_footprint"/>
    <child link="steering_link_left"/>
    <origin rpy="0 0 0" xyz="0.97 0.52 0.0625"/>
    <axis xyz="0 0 1"/>
    <limit effort="10000.0" lower="-0.3" upper="0.3" velocity="2.0"/>
  </joint>
  <gazebo reference="opponent_base_footprint_to_steering_link_left"/>
  <joint name="steering_link_left_to_wheel_FL" type="continuous">
    <origin rpy="1.5707963267948966 0 0" xyz="0 0 -0.037"/>
    <parent link="steering_link_left"/>
    <child link="wheel_FL"/>
    <axis xyz="0 0 1"/>
  </joint>
  <gazebo reference="steering_link_left_to_wheel_FL"/>
  <joint name="opponent_base_footprint_to_steering_link_right" type="revolute">
    <parent link="opponent_base_footprint"/>
    <child link="steering_link_right"/>
    <origin rpy="0 0 0" xyz="0.97 -0.52 0.0625"/>
    <axis xyz="0 0 1"/>
    <limit effort="10000.0" lower="-0.3" upper="0.3" velocity="2.0"/>
  </joint>
  <gazebo reference="opponent_base_footprint_to_steering_link_right"/>
  <joint name="steering_link_right_to_wheel_FR" type="continuous">
    <origin rpy="1.5707963267948966 0 0" xyz="0 0 -0.037"/>
    <parent link="steering_link_right"/>
    <child link="wheel_FR"/>
    <axis xyz="0 0 1"/>
  </joint>
  <gazebo reference="steering_link_right_to_wheel_FR"/>
  <joint name="opponent_base_footprint_to_gps" type="fixed">
    <parent link="opponent_base_footprint"/>
    <child link="gps_link"/>
    <origin rpy="0 0 0" xyz="0.63 0.4 1.27"/>
  </joint>
  <joint name="opponent_base_footprint_to_camera" type="fixed">
    <parent link="opponent_base_footprint"/>
    <child link="camera"/>
    <origin rpy="0 0.2 0" xyz="0.68 0.4 0.8"/>
  </joint>
  <link name="camera_optical">
    <inertial>
      <mass value="0.0001"/>
      <inertia ixx="0.0001" ixy="0" ixz="0" iyy="0.0001" iyz="0" izz="0.0001"/>
    </inertial>
  </link>
  <joint name="camera_to_optical" type="fixed">
    <parent link="camera"/>
    <child link="camera_optical"/>
    <origin rpy="-1.5707963267948966 0 -1.5707963267948966" xyz="0 0 0"/>
  </joint>
  <joint name="opponent_base_footprint_to_imu" type="fixed">
    <parent link="opponent_base_footprint"/>
    <child link="imu_top_link"/>
    <origin rpy="0 0 0" xyz="0.67 0.4 0.67"/>
  </joint>
  <joint name="opponent_base_footprint_to_imu2" type="fixed">
    <parent link="opponent_base_footprint"/>
    <child link="imu_bottom_link"/>
    <origin rpy="0 0 0" xyz="0 0 0.21"/>
  </joint>
  <joint name="opponent_base_footprint_to_4_april" type="fixed">
    <parent link="opponent_base_footprint"/>
    <child link="4_april"/>
    <origin rpy="0 0 0" xyz="-.3 0 0.51"/>
  </joint>
  <joint name="opponent_base_footprint_to_back_mid_april_white" type="fixed">
    <parent link="opponent_base_footprint"/>
    <child link="white"/>
    <origin rpy="0 0 0" xyz="-.29 0 0.51"/>
  </joint>
  <joint name="opponent_base_footprint_to_5_april" type="fixed">
    <parent link="opponent_base_footprint"/>
    <child link="5_april"/>
    <origin rpy="0 0 -0.7853981633974483" xyz="-.21581 .3937 0.51"/>
  </joint>
  <joint name="opponent_base_footprint_to_back_left_april_white" type="fixed">
    <parent link="opponent_base_footprint"/>
    <child link="white_back_left"/>
    <origin rpy="0 0 -0.7853981633974483" xyz="-.20581 .3837 0.51"/>
  </joint>
  <joint name="opponent_base_footprint_to_6_april" type="fixed">
    <parent link="opponent_base_footprint"/>
    <child link="6_april"/>
    <origin rpy="0 0 -1.5707963267948966" xyz=".512 .45 0.51"/>
  </joint>
  <joint name="opponent_base_footprint_to_side_left_april_white" type="fixed">
    <parent link="opponent_base_footprint"/>
    <child link="white_side_left"/>
    <origin rpy="0 0 -1.5707963267948966" xyz=".512 .44 0.51"/>
  </joint>
  <joint name="opponent_base_footprint_to_7_april" type="fixed">
    <parent link="opponent_base_footprint"/>
    <child link="7_april"/>
    <origin rpy="0 0 0.7853981633974483" xyz="1.2414 .3937 0.51"/>
  </joint>
  <joint name="opponent_base_footprint_to_front_left_april_white" type="fixed">
    <parent link="opponent_base_footprint"/>
    <child link="white_front_left"/>
    <origin rpy="0 0 0.7853981633974483" xyz="1.2314 .3837 0.51"/>
  </joint>
  <joint name="opponent_base_footprint_to_0_april" type="fixed">
    <parent link="opponent_base_footprint"/>
    <child link="0_april"/>
    <origin rpy="0 0 0" xyz="1.3256 0 0.51"/>
  </joint>
  <joint name="opponent_base_footprint_to_front_mid_april_white" type="fixed">
    <parent link="opponent_base_footprint"/>
    <child link="white_front_mid"/>
    <origin rpy="0 0 0" xyz="1.3156 0 0.51"/>
  </joint>
  <joint name="opponent_base_footprint_to_1_april" type="fixed">
    <parent link="opponent_base_footprint"/>
    <child link="1_april"/>
    <origin rpy="0 0 -0.7853981633974483" xyz="1.2414 -.3937 0.51"/>
  </joint>
  <joint name="opponent_base_footprint_to_front_right_april_white" type="fixed">
    <parent link="opponent_base_footprint"/>
    <child link="white_front_right"/>
    <origin rpy="0 0 -0.7853981633974483" xyz="1.2314 -.3837 0.51"/>
  </joint>
  <joint name="opponent_base_footprint_to_2_april" type="fixed">
    <parent link="opponent_base_footprint"/>
    <child link="2_april"/>
    <origin rpy="0 0 -1.5707963267948966" xyz=".512 -.3937 0.51"/>
  </joint>
  <joint name="opponent_base_footprint_to_side_right_april_white" type="fixed">
    <parent link="opponent_base_footprint"/>
    <child link="white_side_right"/>
    <origin rpy="0 0 -1.5707963267948966" xyz=".512 -.3837 0.51"/>
  </joint>
  <joint name="opponent_base_footprint_to_3_april" type="fixed">
    <parent link="opponent_base_footprint"/>
    <child link="3_april"/>
    <origin rpy="0 0 0.7853981633974483" xyz="-.21581 -.3937 0.51"/>
  </joint>
  <joint name="opponent_base_footprint_to_back_right_april_white" type="fixed">
    <parent link="opponent_base_footprint"/>
    <child link="white_back_right"/>
    <origin rpy="0 0 0.7853981633974483" xyz="-.20581 -.3837 0.51"/>
  </joint>
  <!-- ******************* Sensors *********************** -->
</robot>
